Workbook

Sheet Budget
A1: Totale kosten | D1: Kosten van thuis | G1: Kosten vooraf | J1: Kosten op reis | O1: Inkomsten
E2: Per maand | H2: Eenmalig | P2: Per maand
A3: Kosten van thuis | B3: =E27 -> 10455.75 | D3: Zorgverzekering | E3: =Verzekeringen!B4 -> 352 | G3: Uitrusting | H3: 0 | J3: Maaltijden en boodschappen | K3: Aantal dagen | L3: Dagbudget | M3: Totaal per land | O3: Salaris
A4: Kosten vooraf | B4: =H27 -> 21551.2 | D4: Woonhuis / reis verzekering | E4: =SUM(Verzekeringen!B5:B15) -> 344.15 | G4: Vaccinaties | H4: 500 | J4: Australië | K4: =COUNTA('Planning simpel'!D39:D86) -> 48 | L4: 75 | M4: =K4*L4 -> 3600 | O4: Salaris Maartje | P4: 4200
A5: Kosten op reis | B5: =M27 -> 60048.913 | D5: Pensioenpremie Bas | E5: 0 | G5: Visa | H5: 400 | J5: Nieuw-Zeeland | K5: =COUNTA('Planning simpel'!D87:D125) -> 39 | L5: 75 | M5: =K5*L5 -> 2925 | O5: Salaris Bas | P5: 3200
A6: Onvoorzien | B6: 5000 | D6: Pensioenpremie Maartje | E6: 0 | G6: Annulerings verzekering (extra) | H6: 400 | J6: Fiji | K6: =COUNTA('Planning simpel'!D31:D38) -> 8 | L6: 175 | M6: =K6*L6 -> 1400
A7: Totaal benodigd | B7: =SUM(B3:B6) -> 97055.863 | D7: Hypotheek | E7: 480 | J7: Thailand & SIN & Doha | K7: 23 | L7: 100 | M7: =K7*L7 -> 2300 | O7: Totaal | P7: =SUM(P4:P6) -> 7400
D8: BGHU | E8: 180 | J8: USA | K8: =COUNTA('Planning simpel'!D2:D29) -> 28 | L8: 150 | M8: =K8*L8 -> 4200 | O8: Overige
A9: Totaal al betaald | B9: =SUM(B10:B12) -> 43527.913 | D9: Nuts | E9: 100 | J9: Tanzania (inclucsief) | K9: =COUNTA('Planning simpel'!D148:D157) -> 10 | L9: 0 | M9: 0 | O9: Hypotheek teruggave | P9: 239
A10: Vluchten | B10: =H12 -> 12749 | D10: tv/internet/telefoon | E10: 120 | O10: Belasting
A11: Accomodatie | B11: =SUMIF('Planning simpel'!L2:L158, "Ja", 'Planning simpel'!I2:I159) -> 29533.913 | D11: levens verzekering | E11: 15 | G11: Vervoer | O11: Kinderbijslag
A12: Excursies | B12: =SUMIF('Excursies en activiteien'!C2:C91, "Ja", 'Excursies en activiteien'!B2:B91) -> 1245 | D12: diverse | E12: 100 | G12: Vliegtickets | H12: ='Vluchten en vervoer'!G29 -> 12749
A13: Bekostiging reis | D13: Auto | E13: 400 | G13: Auto huur | H13: ='Vluchten en vervoer'!G51 -> 4522.2
A14: Salaris | B14: =P7*P26 -> 37000 | D14: Opslagbox voor spullen | E14: 0 | G14: Overig vervoer | H14: ='Vluchten en vervoer'!G96 -> 480 | J14: Uit eten extra | K14: 15 | L14: 150 | M14: =K14*L14 -> 2250
A15: Spaarrekening Wereldreis | B15: 62000 | J15: Totaal en gemiddelde | K15: =SUM(K4:K13) -> 156 | M15: =SUM(M4:M14) -> 16675
A16: Huurinkomsten | B16: =P22 -> 11200 | J16: Accomodatie | O16: Totaal | P16: =SUM(P9:P15) -> 239
A17: Vakantie spraarrekening | B17: 6000 | G17: Benzine (10.000 km) | H17: 2500 | J17: kosten cabin/hotel | K17: ='Planning simpel'!A158 -> 157 | M17: =SUM('Planning simpel'!I4:I159) -> 36952.913 | O17: Huur inkomsten totaal | P17: 11200
A18: Totaal | B18: =SUM(B14:B17) -> 116200
J19: Excursies
A20: Totaal benodigd | B20: =B7 -> 97055.863 | J20: Excursies (gepland) | M20: ='Excursies en activiteien'!B92 -> 5421
A21: Verschil | B21: =B18-B20 -> 19144.137 | J21: Excursies (niet gepland) | M21: 1000
J22: Totaal excursies | M22: =SUM(M20:M21) -> 6421 | O22: Totaal | P22: =SUM(P17:P21) -> 11200
A23: Spaarrekening Wereldreis = huidig bedrag + maandelijkse inleg van €500 | J23: Overige
D24: Totaal per maand | E24: =SUM(E3:E23) -> 2091.15 | M24: =K24*L24 -> 0 | O24: Totaal per maand | P24: =SUM(P7+P16) -> 7639
A25: Vakantie spraarrekening = 16 maanden inleg (€500) vakantie spaarrekening | M25: =K25*L25 -> 0
D26: Aantal maanden op reis | E26: 5 | O26: Aantal maanden op reis | P26: 5
A27: kosten per dag | B27: =B20/K15 -> 622.15297 | D27: Totale kosten van thuis | E27: =E24*E26 -> 10455.75 | G27: Totale kosten vooraf | H27: =SUM(H3:H25) -> 21551.2 | J27: Totale kosten op reis | M27: =M15+M17+M25+M22+M24 -> 60048.913 | O27: Totale kosten van thuis | P27: =((P24*P26)+P17) -> 49395

Sheet Planning simpel
B1: Datum | D1: aantal dagen | E1: Locatie | F1: Vervoer | G1: KM | H1: duur | I1: Kosten | J1: Geboekt | K1: Annuleren | L1: Betaald | M1: Geboekt bij | N1: Ontbijt | O1: Keuken | P1: Zwembad | Q1: Naam
A2: 1 | B2: 46284 | C2: Zaterdag | D2: 1 | E2: ✈️ Aankomst San Francisco 14:00 | I2: 193 | J2: Ja | K2: Ja | L2: Ja | M2: Booking | N2: ja | O2: Nee | P2: ja | Q2: Holliday inn golden gateway
A3: 2 | B3: 46285 | C3: Zondag | D3: 2 | E3: San Francisco | I3: 193 | J3: Ja | K3: Ja | L3: Ja | M3: Booking | N3: ja | O3: Nee | P3: ja | Q3: Holliday inn golden gateway
A4: 3 | B4: 46286 | C4: Maandag | D4: 3 | E4: San Francisco | I4: 193 | J4: Ja | K4: Ja | L4: Ja | M4: Booking | N4: ja | O4: Nee | P4: ja | Q4: Holliday inn golden gateway
A5: 4 | B5: 46287 | C5: dinsdag | D5: 4 | E5: San Francisco → Monterey / Carmel | F5: Auto | G5: 200 | H5: 2.3 | I5: 155 | J5: Ja | K5: Nee | L5: Ja | M5: Direct | N5: Ja | O5: Nee | P5: Nee | Q5: https://www.coltoninn.com/
A6: 5 | B6: 46288 | C6: woensdag | D6: 5 | E6: Monterey → San Simeon (Big Sur route) | F6: Auto | G6: 360 | H6: 6 | I6: 91 | J6: Ja | K6: Nee | L6: Ja | M6: Direct | N6: Ja | O6: Nee | P6: Ja | Q6: https://www.choicehotels.com/en-uk/california/san-simeon/quality-inn-hotels
A7: 6 | B7: 46289 | C7: donderdag | D7: 6 | E7: San Simeon → Santa Barbara | F7: Auto | G7: 150 | H7: 2.15 | I7: 160 | J7: Ja | K7: Ja | L7: Nee | M7: Booking | N7: Nee | O7: Ja | P7: Ja | Q7: Flying Flags RV Resort & Campground
A8: 7 | B8: 46290 | C8: vrijdag | D8: 7 | E8: Santa Barbara → Los Angeles | F8: Auto | G8: 165 | H8: 3 | I8: 285 | J8: Ja | K8: Ja | L8: Ja | M8: VRBO | N8: Nee | O8: Ja | P8: Ja | Q8: Marina del Rey, 13950 Panay Way, Marina del Rey, CA, 90292 Verenigde Staten
A9: 8 | B9: 46291 | C9: zaterdag | D9: 8 | E9: Los Angeles - Venice beach - Venice beach | F9: Auto | G9: 30 | H9: 0.3 | I9: 285 | J9: Ja | K9: Ja | L9: Ja | M9: VRBO | N9: Nee | O9: Ja | P9: Ja | Q9: Marina del Rey, 13950 Panay Way, Marina del Rey, CA, 90292 Verenigde Staten
A10: 9 | B10: 46292 | C10: zondag | D10: 9 | E10: Los Angeles - Venice beach | F10: Auto | I10: 285 | J10: Ja | K10: Ja | L10: Ja | M10: VRBO | N10: Nee | O10: Ja | P10: Ja | Q10: Marina del Rey, 13950 Panay Way, Marina del Rey, CA, 90292 Verenigde Staten
A11: 10 | B11: 46293 | C11: maandag | D11: 10 | E11: Los Angeles - Anaheim | F11: Auto | G11: 30 | H11: 1 | I11: 146 | J11: Ja | K11: Nee | L11: Ja | M11: Booking | N11: Ja | O11: Nee | P11: Ja | Q11: Embassy Suites by Hilton Anaheim South
A12: 11 | B12: 46294 | C12: dinsdag | D12: 11 | E12: Los Angeles - Anaheim | F12: Auto | I12: 146 | J12: Ja | K12: Nee | L12: Ja | M12: Booking | N12: Ja | O12: Nee | P12: Ja | Q12: Embassy Suites by Hilton Anaheim South
A13: 12 | B13: 46295 | C13: woensdag | D13: 12 | E13: Los Angeles → Joshua Tree → Kingman | F13: Auto | G13: 470 | H13: 5.3 | I13: 134 | J13: Ja | K13: Nee | L13: Ja | M13: Booking | N13: Ja | O13: Nee | P13: Ja | Q13: Best Western Plus A Wayfarer's Inn & Suites
A14: 13 | B14: 46296 | C14: donderdag | D14: 13 | E14: Kingman → Grand Canyon | F14: Auto | G14: 230 | H14: 3.3 | I14: 196 | J14: Ja | K14: Ja | L14: Ja | M14: Booking | N14: Nee | O14: Nee | P14: Ja | Q14: Grand Canyon Hotel & Suites
A15: 14 | B15: 46297 | C15: vrijdag | D15: 14 | E15: Grand Canyon → Kayenta | F15: Auto | G15: 200 | H15: 2.3 | I15: 194 | J15: Ja | K15: Nee | L15: Ja | M15: Booking | N15: Ja | O15: Nee | P15: Ja | Q15: Hampton Inn Kayenta Monument Valley
A16: 15 | B16: 46298 | C16: zaterdag | D16: 15 | E16: Bluff (Monument Valley) | F16: Auto | G16: 100 | H16: 1.3 | I16: 300 | J16: Ja | K16: Nee | L16: Ja | M16: Direct | N16: Nee | O16: Nee | P16: Nee | Q16: The View Hotel
A17: 16 | B17: 46299 | C17: zondag | D17: 16 | E17: Bluff (Monument Valley) → Page → Kanab | F17: Auto | G17: 200 | H17: 3 | I17: 180 | J17: Ja | K17: Ja | L17: Nee | M17: Direct | N17: Ja | O17: Nee | P17: Ja | Q17: Holiday Inn Express & Suites Kanab
A18: 17 | B18: 46300 | C18: maandag | D18: 17 | E18: Kanab → Bryce Canyon NP | F18: Auto | I18: 260 | J18: Ja | K18: Nee | L18: Nee | M18: Direct | N18: Nee | O18: Ja | P18: Nee | Q18: https://brycevistas.com/
A19: 18 | B19: 46301 | C19: dinsdag | D19: 18 | E19: Bryce Canyon → Zion NP | F19: Auto | G19: 140 | H19: 2 | I19: 270 | J19: Ja | K19: Ja | L19: Ja | M19: Direct | N19: Nee | O19: Ja | P19: Ja | Q19: https://therivatzion.com/
A20: 19 | B20: 46302 | C20: woensdag | D20: 19 | E20: Zion NP | F20: Auto | I20: 270 | J20: Ja | K20: Ja | L20: Ja | M20: Direct | N20: Nee | O20: Ja | P20: Ja | Q20: https://therivatzion.com/
A21: 20 | B21: 46303 | C21: donderdag | D21: 20 | E21: Zion NP | F21: Auto | I21: 270 | J21: Ja | K21: Ja | L21: Ja | M21: Direct | N21: Nee | O21: Ja | P21: Ja | Q21: https://therivatzion.com/
A22: 21 | B22: 46304 | C22: vrijdag | D22: 21 | E22: Zion NP → Las Vegas | F22: Auto | G22: 310 | H22: 4 | I22: 205 | J22: Ja | K22: Ja | L22: Ja | M22: Airbnb | N22: Nee | O22: Ja | P22: Ja | Q22: MGM Grand Tower C
A23: 22 | B23: 46305 | C23: zaterdag | D23: 22 | E23: Las Vegas | F23: Auto | I23: 205 | J23: Ja | K23: Ja | L23: Ja | M23: Airbnb | N23: Nee | O23: Ja | P23: Ja | Q23: MGM Grand Tower C
A24: 23 | B24: 46306 | C24: zondag | D24: 23 | E24: Las Vegas → Mammoth Lakes | F24: Auto | G24: 530 | H24: 6 | I24: 204 | J24: Ja | K24: Ja | L24: Ja | M24: Expedia | N24: Nee | O24: Ja | P24: Ja | Q24: Juniper springs
A25: 24 | B25: 46307 | C25: maandag | D25: 24 | E25: Mammoth Lakes | F25: Auto | I25: 204 | J25: Ja | K25: Ja | L25: Ja | M25: Expedia | N25: Nee | O25: Ja | P25: Ja | Q25: Juniper springs
A26: 25 | B26: 46308 | C26: dinsdag | D26: 25 | E26: Mammoth Lakes → Yosemite NP | F26: Auto | G26: 170 | H26: 3.3 | I26: 271 | J26: Ja | K26: Nee | L26: Ja | M26: Booking | N26: Nee | O26: Ja | P26: Ja | Q26: Yosemite View Lodge
A27: 26 | B27: 46309 | C27: woensdag | D27: 26 | E27: Yosemite NP | F27: Auto | I27: 271 | J27: Ja | K27: Nee | L27: Ja | M27: Booking | N27: Nee | O27: Ja | P27: Ja | Q27: Yosemite View Lodge
A28: 27 | B28: 46310 | C28: donderdag | D28: 27 | E28: Yosemite NP → San Francisco | F28: Auto | G28: 310 | H28: 4.15 | I28: 133 | J28: Ja | K28: Nee | L28: Ja | M28: Booking | N28: Nee | O28: Nee | P28: Nee | Q28: Nob Hill Motor Inn
A29: 28 | B29: 46311 | C29: vrijdag | D29: 28 | E29: San Francisco ✈️ Vertrek 22:55 | I29: 133 | J29: Ja | K29: Nee | L29: Ja | M29: Booking | N29: Nee | O29: Nee | P29: Nee | Q29: Nob Hill Motor Inn
A30: 29 | B30: 46312 | C30: zaterdag | D30: 0 | E30: Volgende dag aankomst + 1 dag tijdverschil
A31: 30 | B31: 46313 | C31: zondag | D31: 1 | E31: Nadi aankomst 05:00 (ochtend) Plantation | I31: 240 | J31: Ja | K31: Ja | L31: Nee | M31: Direct | N31: Nee | O31: Nee | P31: Ja | Q31: Plantation resort
A32: 31 | B32: 46314 | C32: maandag | D32: 2 | E32: Plantation | F32: x | H32: 1u45 | I32: 240 | J32: Ja | K32: Ja | L32: Nee | M32: Direct | N32: Nee | O32: Nee | P32: Ja | Q32: Plantation resort
A33: 32 | B33: 46315 | C33: dinsdag | D33: 3 | E33: Plantation / Port Denarau | F33: x | I33: 250 | J33: Ja | K33: Nee | L33: Ja | M33: Booking | N33: Nee | O33: Ja | P33: Ja | Q33: The Palms Denarau Fiji
A34: 33 | B34: 46316 | C34: woensdag | D34: 4 | E34: Port Denarau | F34: x | I34: 250 | J34: Ja | K34: Nee | L34: Ja | M34: Booking | N34: Nee | O34: Ja | P34: Ja | Q34: The Palms Denarau Fiji
A35: 34 | B35: 46317 | C35: donderdag | D35: 5 | E35: Kuata (1/3) | F35: x | H35: 2u15 | I35: 291 | J35: Ja | K35: Ja | L35: Ja | M35: Direct | N35: Ja | O35: Nee | P35: Ja | Q35: https://www.barefootkuatafiji.com/
A36: 35 | B36: 46318 | C36: vrijdag | D36: 6 | E36: Kuata (2/3) | F36: x | I36: 291 | J36: Ja | K36: Ja | L36: Ja | M36: Direct | N36: Ja | O36: Nee | P36: Ja | Q36: https://www.barefootkuatafiji.com/
A37: 36 | B37: 46319 | C37: zaterdag | D37: 7 | E37: Kuata (3/3) | F37: x | I37: 291 | J37: Ja | K37: Ja | L37: Ja | M37: Direct | N37: Ja | O37: Nee | P37: Ja | Q37: https://www.barefootkuatafiji.com/
A38: 37 | B38: 46320 | C38: zondag | D38: 8 | E38: Einde middag Terug naar Denarau | F38: x | H38: 2u45 | I38: 150 | J38: Ja | K38: Ja | L38: Ja | M38: Booking | N38: Ja | O38: Nee | P38: Ja | Q38: Tokatoka
A39: 38 | B39: 46321 | C39: maandag | D39: 1 | E39: Fiji➔ Brisbane | I39: 180 | J39: Ja | K39: Nee | L39: Ja | M39: Booking | N39: Nee | O39: Ja | P39: Ja | Q39: https://www.booking.com/hotel/au/brisbane-1.nl.html?label=gen173nr-10CAso6AFCEWVpbGVlbnMtdHJlZXMtaW5uSBxYBGipAYgBAZgBM7gBF8gBDNgBA-gBAfgBAYgCAagCAbgCw6uNzAbAAgHSAiQ0MWI3MmEyMS04MDI1LTRhYTUtYjVlZi1iOTc1Y2ViNWQ5ZDDYAgHgAgE&sid=58385233827b3dc4126ecb2cfd20fd81&aid=304142
A40: 39 | B40: 46322 | C40: dinsdag | D40: 2 | E40: Brisbane | F40: x | G40: - | H40: - | I40: 180 | J40: Ja | K40: Nee | L40: Ja | M40: Booking | N40: Nee | O40: Ja | P40: Ja | Q40: https://www.booking.com/hotel/au/brisbane-1.nl.html?label=gen173nr-10CAso6AFCEWVpbGVlbnMtdHJlZXMtaW5uSBxYBGipAYgBAZgBM7gBF8gBDNgBA-gBAfgBAYgCAagCAbgCw6uNzAbAAgHSAiQ0MWI3MmEyMS04MDI1LTRhYTUtYjVlZi1iOTc1Y2ViNWQ5ZDDYAgHgAgE&sid=58385233827b3dc4126ecb2cfd20fd81&aid=304142
...

Sheet Accomodatie
A1: Accomodatie
A2: Aankomst datum | B2: Vertrek datum | C2: Naam Accomodatie | D2: Reserveringsnummer | E2: Kosten | F2: inchecken (tijd) | G2: uitchecken (tijd) | H2: Ontbijt | I2: Telefoonnummer | J2: Adres
A3: 46284 | B3: 46287 | C3: Holliday inn golden gateway | D3: 6004927844 | E3: 584.06 | F3: 0.66666667 | G3: 0.45833333 | H3: Ja | I3: +1 415 441 4000 | J3: 1500 Van Ness Ave, San Francisco, CA 94109, Verenigde Staten
A4: 46287 | B4: 46288 | C4: Colton Inn | D4: CICA05091266 | E4: 155.98 | F4: 0.625 | G4: 0.45833333 | H4: Ja | I4: +1 831 649 6500 | J4: 707 Pacific Street | Monterey, CA 93940
A5: 46288 | B5: 46289 | C5: Quality Inn near Hearst Castle (San Simeon) | D5: 12693981 | E5: 91.3 | F5: 0.625 | G5: 0.45833333 | H5: Nee | I5: +1 805 927 3998 | J5: 9260 Castillo Drive, San Simeon, CA 93452, US
A6: 46289 | B6: 46290 | C6: Flying Flags RV Resort & Campground | D6: 5411636117 | E6: 161 | F6: 0.66666667 | G6: 0.45833333 | H6: Nee | I6: +1 805 688 3716 | J6: 180 Avenue of Flags, Buellton, 93427, Verenigde Staten
A7: 46290 | B7: 46293 | C7: Airbnb Marina del Rey | D7: HM23KJD38X | E7: 641 | F7: 0.66666667 | G7: 0.41666667 | H7: Nee | I7: Niet openbaar | J7: 14000 Palawan Way, Marina del Rey, CA 90292, United States
A8: 46293 | B8: 46295 | C8: Embassy Suites by Hilton Anaheim South | D8: 6248261201 | E8: 292 | F8: 0.66666667 | G8: 0.45833333 | H8: Ja | I8: +1 714 539 3300 | J8: 11767 Harbor Boulevard, Garden Grove, Anaheim, CA 92840, Verenigde Staten
A9: 46295 | B9: 46296 | C9: Best Western Plus A Wayfarer's Inn & Suites (Kingman) | D9: 5722837090 | E9: 134 | F9: 0.625 | G9: 0.45833333 | H9: Ja | I9: +1 928 753 6271 | J9: 2815 East Andy Devine Avenue, Kingman, AZ 86401, Verenigde Staten
A10: 46296 | B10: 46297 | C10: Grand Canyon Hotel & Suites | D10: 6821604479 | E10: 197.88 | F10: 0.66666667 | G10: 0.45833333 | H10: Nee | I10: +1 928 638 3000 | J10: 226 Highway 64, Tusayan, AZ 86023, Verenigde Staten
A11: 46297 | B11: 46298 | C11: Hampton Inn Kayenta Monument Valley | D11: 6984657657 | E11: 194 | F11: 0.66666667 | G11: 0.41666667 | H11: Ja | I11: +1 928 697 3170 | J11: US Highway 160, Kayenta, AZ 86033, Verenigde Staten
A12: 46298 | B12: 46299 | C12: The View Campground/Hotel (Monument Valley) | D12: 128167 (online: TVCUT05056231) | E12: 333.49 | F12: 0.66666667 | G12: 0.45833333 | H12: Nee | I12: +1 435 727 5555 | J12: PO Box 360457, Monument Valley, UT 84536 (geen straatadres vermeld)
A13: 46299 | B13: 46300 | C13: Holiday Inn Express & Suites Kanab | D13: 29639006 | E13: 138.92 | F13: 0.66666667 | G13: 0.45833333 | H13: Ja | I13: +1 435 644 3100 | J13: 217 South 100 East, Kanab, UT 84741, United States
A14: 46300 | B14: 46301 | C14: Bryce Vistas (Claron Suite) | D14: 80799875 | E14: 265.55 | F14: 0.66666667 | G14: 0.45833333 | H14: Nee | I14: +1 435 383 2900 | J14: Niet vermeld in e-mail (Bryce Vistas, Zuid-Utah)
A15: 46301 | B15: 46304 | C15: Zion Park Motel | D15: 5594993241 | E15: 744.44 | F15: 0.625 | G15: 0.4375 | H15: Nee | I15: +1 435 772 3251 | J15: 865 Zion Park Blvd, Springdale, 84767, Verenigde Staten
A16: 46304 | B16: 46306 | C16: The Signature at MGM Grand (Las Vegas, Airbnb) | D16: HM4F4WTDMK | E16: 409 | F16: 0.625 | G16: 0.45833333 | H16: Nee | I16: +1 702 797 6000 | J16: Tower C, 125 East Harmon Avenue 17-818, Las Vegas, NV 89109, United States
A17: 46306 | B17: 46308 | C17: Juniper Springs Resort (Mammoth Lakes) | D17: 72070151578100 | E17: 407.41 | F17: 0.66666667 | G17: 0.45833333 | H17: Nee | I17: +1 760 934 1102 | J17: 4000 Meridian Blvd, Mammoth Lakes, CA 93546, Verenigde Staten
A18: 46308 | B18: 46310 | C18: Yosemite View Lodge | D18: 5638749450 | E18: 544.56 | F18: 0.66666667 | G18: 0.45833333 | H18: Nee | I18: +1 209 379 2681 | J18: 11136 Highway 140, El Portal, CA 95318, Verenigde Staten
A19: 46310 | B19: 46312 | C19: Nob Hill Motor Inn (San Francisco) | D19: 5638746431 | E19: 266.43 | F19: 0.625 | G19: 0.45833333 | H19: Nee | I19: +1 415 775 8160 | J19: 1630 Pacific Avenue, Russian Hill, San Francisco, CA 94109, Verenigde Staten
A20: 46313 | B20: 46315 | C20: Plantation resort Fiji | D20: 70810566 | E20: 504.7 | F20: 0.625 | G20: 0.45833333 | H20: Nee | I20: +679 673 4777 | J20: Malolo Lailai, Nadi, Fiji
A21: 46315 | B21: 46317 | C21: The Palms Denarau | D21: 5361293748 | E21: 521.84 | F21: 0.625 | G21: 0.45833333 | H21: Nee | I21: +679 675 0104 | J21: P O Box PD120, Port Denarau, Nadi, Denarau, Fiji
A22: 46317 | B22: 46320 | C22: Kuata Island | D22: 37620 | E22: 1263.34 | F22: 0.625 | G22: 0.45833333 | H22: Ja | I22: +679 895 2090 | J22: Kuata island
A23: 46320 | B23: 46321 | C23: Tokatoka Resort Hotel | D23: 5317923311 | E23: 150 | F23: 0.625 | G23: 0.45833333 | H23: Nee | I23: +679 672 0222 | J23: Nadi Airport, 9305 Nadi, Fiji
A24: 46321 | B24: 46324 | C24: Brisbane One Apartments by CLLIX | D24: 6755476861 | E24: 477.01 | F24: 0.58333333 | G24: 0.41666667 | H24: Nee | I24: +61 7 3255 0889 | J24: 1 Cordelia Street, South Brisbane, 4101 Brisbane, Australië
A25: 46324 | B25: 46327 | C25: Broken Head Nature Cabins | D25: HMRBDPZKYE | E25: 530 | F25: 0.625 | G25: 0.41666667 | H25: Nee | I25: Niet openbaar | J25: 1 Bundaleer Road, Broken Head, NSW 2481
A26: 46327 | B26: 46328 | C26: Rosella's On Springbrook | D26: 6766283993 | E26: 175.69 | F26: 0.58333333 | G26: 0.41666667 | H26: Nee | I26: +61 427 682 856 | J26: 8 Canyon Parade, 4213 Springbrook, Australië
A27: 46328 | B27: 46330 | C27: Woning in Rainbow Beach | D27: HMD4TRTHAY | E27: 247.65 | F27: 0.625 | G27: 0.41666667 | H27: Nee | I27: Niet openbaar | J27: Rainbow Shores Drive 48/5, Rainbow Beach, Queensland 4581, Australië
A28: 46330 | B28: 46332 | C28: Myuna Holiday Apartments | D28: 5045905618 | E28: 383.45 | F28: 0.625 | G28: 0.41666667 | H28: Nee | I28: +61 7 5447 5588 | J28: 19 Katharina Street, 4567 Noosa Heads, Australië
A29: 46332 | B29: 46334 | C29: Blackwattle Farm (Tall Gum Tiny House, Glass House Mountains) | D29: 562738 | E29: 379.53 | F29: 0.58333333 | G29: 0.41666667 | H29: Ja | I29: +61 408 536 815 | J29: 123 Old Peachester Road, Beerwah, Queensland, Australia
A30: 46334 | B30: 46341 | C30: Airbnb Port Douglas - Reef Nest | D30: HMB3YMXBCS | E30: 898.39 | F30: 0.58333333 | G30: 0.41666667 | H30: Nee | I30: Niet openbaar | J30: 19-37 Saint Crispins Avenue Unit 28, Port Douglas, QLD 4877, Australia
A31: 46341 | B31: 46342 | C31: Cape Trib Beach House | D31: 5293053886 | E31: 137.73 | F31: 0.58333333 | G31: 0.41666667 | H31: Nee | I31: +61 7 4098 0030 | J31: 7 Rykers Road, 4873 Cape Tribulation, Australië
A32: 46342 | B32: 46343 | C32: Chambers Wildlife Rainforest Lodges (Tablelands) | D32: 6645797482 | E32: 128.55 | F32: 0.58333333 | G32: 0.41666667 | H32: Nee | I32: +61 7 4095 3754 | J32: Eacham Close, 4884 Lake Eacham, Australië
A33: 46343 | B33: 46344 | C33: Cairns Colonial Club Resort | D33: 6817625650 | E33: 114 | F33: 0.58333333 | G33: 0.41666667 | H33: Nee | I33: +61 7 4053 8800 | J33: 18-26 Cannon St, Manunda QLD 4870, Australië
A34: 46344 | B34: 46348 | C34: Airbnb Sydney - Cremorne Point | D34: HMPQJZ93WF | E34: 984 | F34: 0.625 | G34: 0.41666667 | H34: Nee | I34: Niet openbaar | J34: 5 Milson Rd, Cremorne Point NSW 2090, Australia
A35: 46348 | B35: 46351 | C35: Holiday Haven Bendalong (Bayview) | D35: 409217 | E35: 446.87 | F35: 0.58333333 | G35: 0.41666667 | H35: Nee | I35: +61 2 4444 8860 | J35: 1 Waratah Street, Bendalong, New South Wales 2539, Australia
A36: 46351 | B36: 46353 | C36: Discovery Parks - Narooma Beach | D36: #J-5894241 | E36: 230.14 | F36: 0.58333333 | G36: 0.41666667 | H36: Nee | I36: +61 2 4402 3247 | J36: Niet vermeld in e-mail (park: Narooma, NSW)
A37: 46353 | B37: 46354 | C37: Discovery Parks - Eden | D37: #J-5894300 | E37: 137.86 | F37: 0.58333333 | G37: 0.41666667 | H37: Nee | I37: +61 2 6496 1572 | J37: 731 Princes Hwy, Boydtown NSW 2551, Australië
A38: 46354 | B38: 46355 | C38: BIG4 Traralgon Park Lane Holiday Park | D38: 6218660708 | E38: 145.17 | F38: 0.58333333 | G38: 0.41666667 | H38: Nee | I38: +61 3 5174 6749 | J38: 5353 Princes Highway, 3844 Traralgon, Australië
A39: 46355 | B39: 46357 | C39: Wilsons Prom Accommodation - Tidal River Cabins | D39: 16014854 | E39: 438.14 | F39: 0.58333333 | G39: 0.41666667 | H39: Nee | I39: +61 3 8427 2122 | J39: Tidal River, Wilsons Promontory National Park, VIC (exact adres niet vermeld)
A40: 46357 | B40: 46360 | C40: Warburton Holiday Park (Riverside Two Bedroom Ensuite Cabin) | D40: 3218364 | E40: 332.21 | F40: 0.58333333 | G40: 0.41666667 | H40: Nee | I40: +61 3 5966 2277 | J40: 30 Woods Point Rd, Warburton VIC 3799, Australia
...

Sheet Verzekeringen
A2: Kosten verzekeringen
A3: Type verzekering | B3: Kosten per maand | C3: verzekeraar | D3: Polis nummer
A4: CZ basis + aanvullend: alle medische zorg | B4: 352 | C4: CZ | D4: Bas 484990306 Maartje 484990276 Liz 484990284 Isa 484990292
A5: Special ISIS Super + Basis: de volwaardige reisverzekering | B5: 168 | C5: Special isis
A6: OOM annuleringsverzekering: annulering vóór vertrek | B6: 44.15 | C6: OOM | D6: TIB7122782
A7: OOM Achtergebleven Woonhuis: opstal en inboedel | B7: 132 | C7: OOM
A11: afzonderlijke huurauto-/camperverzekeringen | C11: meerdere
A16: totaal | B16: =SUM(B3:B15) -> 696.15

Sheet Excursies en activiteien
A1: Kosten excursies en activiteiten | C1: Betaald | D1: Geboekt | E1: Datum | F1: Adres | G1: Website
A2: Amerika
A3: America the Beautiful pas | B3: 80 | C3: Ja | D3: Ja | G3: https://www.nps.gov/planyourvisit/passes.htm
A4: Fietshuur San fransisco | B4: 160 | E4: 46286 | F4: 2715 Hyde Street, San Francisco, CA 94109, Verenigde Staten | G4: https://www.blazingsaddles.com/san-francisco/locations
A5: Bodie Ghost Town | B5: 26 | E5: 46307 | F5: Highway 270, Bridgeport, CA 93517, Verenigde Staten | G5: https://www.parks.ca.gov/bodie
A6: The Sphere Experience Las Vegas | B6: 450 | E6: 46305 | F6: 255 Sands Avenue, Las Vegas, NV 89169, Verenigde Staten | G6: https://www.thesphere.com/shows/the-sphere-experience
A7: Antelope Canyon X general tour | B7: 210 | C7: Ja | D7: Ja | E7: 46299 | F7: Milepost 308, Highway AZ-98, Page, AZ 86040, Verenigde Staten | G7: https://www.antelopecanyon-x.com/canyon-tours/antelope-canyon-x-hiking-tour/
A8: Monument Valley | B8: 30 | E8: 46298 | F8: Indian Route 42, Oljato-Monument Valley, AZ 84536, Verenigde Staten | G8: https://navajonationparks.org/navajo-tribal-parks/monument-valley/
A9: Disney anaheim | B9: 405 | C9: Ja | D9: Ja | E9: 46294 | F9: 1313 Disneyland Drive, Anaheim, CA 92802, Verenigde Staten | G9: https://disneyland.disney.go.com/
A10: Santa Monica Pier | B10: 100 | E10: 46292 | F10: 200 Santa Monica Pier, Santa Monica, CA 90401, Verenigde Staten | G10: https://www.santamonicapier.org/
B11: 0
A13: Fiji
A14: ecotrax | B14: 250 | C14: Ja | D14: Ja | E14: 46316 | F14: Cuvu Back Road, Cuvu, Fiji | G14: https://www.ecotrax.com.fj/location
A15: Shark dive kuata island | B15: 100 | E15: 46318 | G15: https://www.barefootsharkencounters.com/the-awakening-shark-dive-fiji
A17: Australie
A18: Australian Zoo | B18: 125 | E18: 46333 | F18: 1638 Steve Irwin Way, Beerwah QLD 4519, Australië | G18: https://australiazoo.com.au/
A19: Noosa Everglades SELF GUIDED Kayak | B19: 165 | E19: 46331 | F19: 204 Lake Flat Road, Elanda Point National Park Canoe Launch Area, Boreen Point QLD 4565, Australië | G19: https://www.kanukapersaustralia.com/contact/meeting-place/
A20: Noosa Dolphin Kayak Tour | B20: 410 | E20: 46332 | F20: 60 Noosa Drive, Noosa Heads QLD 4567, Australië | G20: https://www.epicoceanadventures.com.au/dolphin-view-sea-kayak-tour/
A23: Waterfall route | B23: 0 | E23: 46342 | G23: https://tropicalnorthqueensland.org.au/listing/itinerary/waterfall-circuit/
A24: Crater lakes | B24: 0 | E24: 46342 | F24: Lake Eacham Road, Lake Eacham QLD 4884 | G24: https://parks.qld.gov.au/parks/crater-lakes
A25: Baramundi fishing | B25: 115 | E25: 46340 | F25: Lot 3, Vixies Road, Wonga Beach QLD 4873, Australië | G25: https://www.hookabarra.com/
A26: Low iles snorkeling | B26: 330 | E26: 46337 | F26: Crystalbrook Marina, 44 Wharf Street, Port Douglas QLD 4877, Australië | G26: https://wavedancerlowisles.com/
A27: Wildlife habitat | B27: 75 | E27: 46338 | F27: 1 Port Douglas Road, Port Douglas QLD 4877, Australië | G27: https://www.wildlifehabitat.com.au/
A28: Beach horseback riding | B28: 120 | E28: 46336 | F28: 3812 Cape Tribulation Road, Cape Tribulation QLD 4873, Australië | G28: https://www.capetribhorserides.com.au/
A29: Daintree Discovery Centre | B29: 60 | E29: 46336 | F29: 24 Tulip Oak Road, Cow Bay QLD 4873, Australië | G29: https://www.discoverthedaintree.com/
A30: Mossman Gorge | B30: 20 | E30: 46335 | F30: 212R Mossman Gorge Road, Mossman Gorge QLD 4873, Australië | G30: https://www.mossmangorge.com.au/
A31: kuranda butterfly sanctuary | B31: 35 | E31: 46343 | F31: 8 Rob Veivers Drive, Kuranda QLD 4881, Australië | G31: https://australianbutterflies.com/
A32: WAGS boottocht | B32: 0 | E32: 46337 | F32: 1 Spinnaker Close, Port Douglas QLD 4877, Australië | G32: https://www.portdouglasyachtclub.com.au/
A34: Australian Museum | B34: 0 | E34: 46347 | F34: 1 William Street, Sydney NSW 2010, Australië | G34: https://australian.museum/
A35: Pylon Lookout & Museum (harbour bridge) | B35: 50 | E35: 46345 | F35: South-East Pylon, Sydney Harbour Bridge, Sydney NSW 2000, Australië | G35: https://www.bridgemuseum.com.au/
A36: Macquarie’s Chair & Royal Botanic Gardens | B36: 0 | E36: 46347 | F36: Mrs Macquaries Road, Sydney NSW 2000, Australië | G36: https://www.botanicgardens.org.au/royal-botanic-garden-sydney
A37: Sydney Harbour ferry dagtocht | B37: 30 | E37: 46345 | G37: https://transportnsw.info/travel-info/ways-to-get-around/ferry
B38: 0
A39: Pebbly beach | B39: 0 | E39: 46351 | F39: Pebbly Beach Road, Pebbly Beach NSW 2536, Australië | G39: https://www.nationalparks.nsw.gov.au/things-to-do/picnic-areas/pebbly-beach-picnic-area
A40: Durras North Beach | B40: 0 | E40: 46351 | F40: North Durras Road, Durras North NSW 2536, Australië | G40: https://www.nsw.gov.au/visiting-and-exploring-nsw/locations-and-attractions/north-durras-beach
B41: 0
A42: Warburton River Tubing | B42: 135 | E42: 46357 | F42: Warburton Cricket Club, 3455–3457 Warburton Highway, Warburton VIC 3799, Australië | G42: https://www.warburtonadventure.com.au/adventures/self-guided-river-tubing-adventure/
A43: Nationaal park Great Otway | B43: 0 | E43: 46361 | F43: Great Ocean Road, Lorne VIC 3232, Australië | G43: https://www.parks.vic.gov.au/places-to-see/parks/great-otway-national-park
A44: Hanging Rock | B44: 0 | E44: 46364 | F44: 139 South Rock Road, Woodend VIC 3442, Australië | G44: https://www.mrsc.vic.gov.au/See-Do/Our-Region/Natural-Attractions/Hanging-Rock/Plan-Your-Visit
A45: Yarra ranges NT | B45: 0 | E45: 46358 | G45: https://www.parks.vic.gov.au/places-to-see/parks/yarra-ranges-national-park
...

Sheet Vluchten en vervoer
A2: vliegtickets
A3: Vertrek datum | B3: Vertrek tijd | C3: Van | D3: Naar | E3: Aankomst datum | F3: Aankomst rijd | G3: Kosten | H3: Vlucht Nummer | I3: Stoelen
A4: 46284 | B4: 0.32986111 | C4: Amsterdam | D4: Londen (Heathrow) | E4: 46284 | F4: 0.34375 | G4: 2043 | H4: BA0445 | I4: Nog niet gekozen
A5: 46284 | B5: 0.44791667 | C5: Londen (Heathrow) | D5: San Francisco | E5: 46284 | F5: 0.57638889 | G5: 0 | H5: BA0285 | I5: 30A, 30B, 31A, 31B
A6: 46311 | B6: 0.95486111 | C6: San Francisco | D6: Nadi (Fiji) | E6: 46313 | F6: 0.22222222 | G6: 1100 | H6: FJ871 | I6: 12A, 12B, 11A, 11B
A7: 46321 | B7: 0.34722222 | C7: Nadi (Fiji) | D7: Brisbane | E7: 46321 | F7: 0.44097222 | G7: 741 | H7: FJ921 | I7: 12A, 12B, 11A, 11B
A8: 46334 | B8: 0.48263889 | C8: Brisbane | D8: Cairns | E8: 46334 | F8: 0.58333333 | G8: 440 | H8: VA783 | I8: 17A, 18A, 17B, 18B
A9: 46344 | B9: 0.45486111 | C9: Cairns | D9: Sydney | E9: 46344 | F9: 0.62152778 | G9: 440 | H9: VA1416 | I9: 17A, 18A, 17B, 18B
A10: 46369 | B10: 0.50347222 | C10: Melbourne | D10: Christchurch | E10: 46369 | F10: 0.72222222 | G10: 1015 | H10: JQ171 | I10: 11A, 10A, 10B, 11B
A11: 46408 | B11: 0.47222222 | C11: Auckland | D11: Singapore | E11: 46408 | F11: 0.70486111 | G11: 1200 | H11: SQ4284 | I11: Nog niet gekozen
A12: 46412 | B12: 0.54166667 | C12: Singapore | D12: Phuket | E12: 46412 | F12: 0.58680556 | G12: 570 | H12: SQ732 | I12: 51A, 52A, 51B, 52B
A13: 46427 | B13: 0.34722222 | C13: Phuket | D13: Doha | E13: 46427 | F13: 0.47569444 | G13: 1300 | H13: QR843 | I13: 27J, 27K, 28J, 28K
A14: 46430 | B14: 0.35069444 | C14: Doha | D14: Tanzania (Kilimanjaro) | E14: 46430 | F14: 0.69097222 | G14: 1300 | H14: QR1476 | I14: 27J, 27K, 28J, 28K
A15: 46440 | B15: 0.90972222 | C15: Kilimanjaro (Tanzania) | D15: Amsterdam | E15: 46441 | F15: 0.31944444 | G15: 2600 | H15: KL0569 | I15: 35A, 35B, 34C, 35C
F29: totaal | G29: =SUM(G4:G28) -> 12749
A32: Auto en camper huur
A33: Ophaal datum | B33: Ophaal tijd | C33: Ophaal locatie | D33: Inlever locatie | E33: inlever datum | F33: Inlever tijd | G33: Kosten | H33: Reserverings nummer | I33: overige
A34: 46287 | B34: 0.41666667 | C34: Budget Howard Street 821 Howard Street San Fransisco 94103 | D34: San Francisco Airport (780 McDonnell Road) | E34: 46311 | F34: 0.83333333 | G34: 1153.1 | H34: 740.401.507 | I34: Toyota RAV4 of vergelijkbaar, Budget, tel. +1 415 957 9998
A35: 46324 | B35: 0.41666667 | C35: Hertz Brisbane Downtown, 55 Charlotte St, Brisbane City QLD 4000, Australië | D35: Hertz, Airport Dr, Brisbane Airport QLD 4007, Australië | E35: 46334 | F35: 0.39583333 | G35: 380 | H35: 711.800.522 | I35: Subaru Forester of vergelijkbaar, Hertz
A36: 46334 | B36: 0.58333333 | C36: Cairns Luchthaven (CNS) | D36: Cairns Luchthaven (CNS) | E36: 46344 | F36: 0.375 | G36: 239.1 | H36: D012668926 | I36: MG HS of vergelijkbaar (Standaard SUV), Bargain Car Rentals
A37: 46348 | B37: 0.45833333 | C37: Sixt Domain Carpark, 52 sir John Young Cresent, Sydney | D37: Shop 10, Southern Cross Station, Docklands VIC 3008 | E37: 42714 | F37: 0.45833333 | G37: 1250 | H37: 9.731.393.908 | I37: Mitsubishi Eclips of vergelijkbaar (Standaard SUV)
A38: 46372 | B38: 0.45833333 | C38: Christchurch airport, 170 Orchard Road Harewood | D38: Auckland downtown 60-64 The Strand Parnell | E38: 46406 | F38: 0.45833333 | G38: 1500 | H38: U-509894 | I38: Mitsubishi Outlander of vergelijkbaar (Premium SUV), Snap Rentals, borg NZD 2.000
F51: totaal | G51: =SUM(G34:G50) -> 4522.2
A54: Boten / bussen / trein / taxi
A55: reis datum vertrek | B55: Vertrek tijd | C55: Vertrek locatie | D55: Aankomst locatie | E55: aankomst datum | F55: aankomst tijd | G55: Kosten | H55: Reserverings nummer | I55: overige
C63: Thailand | G63: 480
F96: totaal | G96: =SUM(G56:G95) -> 480

Sheet To Do
A1: Fase | B1: Taak | C1: Details/Notities | D1: Status
A2: 45950 | B2: school – eerste overleg | C2: Afspraak met school en leerplicht; globaal plan voor onderwijs en verslaglegging. | D2: x
A3: 45985 | B3: Budget & noodbuffer bepalen | C3: Groffe raming kosten per land + noodbuffer bepalen; aparte spaarrekening/nood-creditcard kiezen. | D3: x
A4: 45985 | B4: Route & verblijfsduur per land definitief maken | C4: Data-blokken per land (USA, Fiji, Australië, NZ, Thailand, Tanzania) vastleggen; nodig voor verzekeringen/visa. | D4: x
A5: 45985 | B5: Hoofdvliegtickets boeken | C5: Intercontinentale vluchten (bijv. AMS–LA, LA–Fiji, Fiji–Aus, NZ–Thailand, Thailand–Tanzania, terug naar NL); kunnen ca. 11 maanden voor vertrek worden geboekt – nu oppakken. | D5: x
A6: 45992 | B6: Paspoorten Aanvragen | C6: Aflopende data checken; moeten minstens 6 maanden geldig zijn na terugkomst; zo nodig verlengen plannen. | D6: x
A8: 46023 | B8: Langdurige reisverzekering uitzoeken | C8: Werelddekking, medische kosten, repatriëring, sport; polisvoorwaarden vergelijken.
A9: 46023 | B9: Annuleringsverzekering kiezen | C9: Let op samengestelde reis (veel losse vluchten/accommodaties); voorwaarden goed checken. | D9: x
A10: 46023 | B10: Aansprakelijkheid & rechtsbijstand checken | C10: Werelddekking en gezinsdekking controleren; evt. upgraden.
A11: 46023 | B11: Basiszorgverzekering checken | C11: Checken hoe doorlopende dekking werkt bij 5 maanden weg; BRP ingeschreven blijven. | D11: x
A12: 46023 | B12: Vluchten Australie Nieuw Zeeland boeken | C12: Welke vluchten binnen landen/ tussen landen al geboekt zijn en welke nog moeten; in sheet verwerken. | D12: x
A14: 46054 | B14: GGD-reisadvies plannen | C14: Afspraak maken voor vaccinatie-advies voor alle landen; tijdig plannen i.v.m. series. | D14: x
A15: 46054 | B15: Tandarts- en huisartscontrole | C15: Controle voor vertrek; medicijnen op recept regelen + Engelstalige verklaring indien nodig. | D15: x
A16: 46054 | B16: Medische & bankmachtigingen regelen | C16: Toestemmingen voor elkaar/thuisfront; bankvolmachten; kopieën ID’s en paspoorten.
A18: 46083 | B18: Vluchten Thailand en Tanzania boeken | C18: Welke vluchten binnen landen/ tussen landen al geboekt zijn en welke nog moeten; in sheet verwerken. | D18: x
A19: 46082 | B19: Verzekeringen definitief afsluiten | C19: Reis-, annulerings-, aansprakelijkheid en eventuele aanvullingen daadwerkelijk afsluiten.
A20: 46082 | B20: Vaccinaties starten/afronden | C20: Eerste prikken zetten; series op tijd afronden voor vertrek. | D20: x
A21: 46082 | B21: Internationaal rijbewijs regelen | C21: Voor VS en Australië; bij ANWB aanvragen.
A22: 46082 | B22: Schoolafspraken vastleggen | C22: Zwarte-op-wit afspraken over leerdoelen, portfolio en terugkoppeling na de reis. | D22: x
A23: 46082 | B23: Huurders woning zoeken | C23: Huisoppas/onderverhuur | D23: x
A25: 46113 | B25: Onderwijsplan kinderen uitwerken | C25: Basisstructuur: dagelijks lezen, 3–4x per week rekenen/taal; materialen/apps selecteren. | D25: x
A26: 46113 | B26: ESTA aanvragen (USA) | C26: Voor alle gezinsleden; geldig tot 2 jaar, maar ruim op tijd regelen. | D26: x
A27: 46113 | B27: Visa/ETA Australië regelen | C27: eVisitor/ETA voor Australië; voorwaarden nalezen. | D27: x
A28: 46113 | B28: NZeTA + IVL aanvragen (Nieuw-Zeeland) | C28: Online aanvraag; ook voor kinderen.
A29: 46113 | B29: Visa-check overige landen | C29: Thailand, Tanzania, Fiji: actuele eisen checken; noteren wat wanneer aangevraagd moet worden. | D29: x
A31: 46143 | B31: Extra betaalmiddelen regelen | C31: Tweede creditcard per volwassene; limieten verhogen; reisnotitie bij bank. | D31: x
A32: 46143 | B32: Wise/Revolut account instellen | C32: Rekening openen, kaarten bestellen, testtransactie doen; budgetten per valuta instellen. | D32: x
A33: 46143 | B33: Thuisfront/contactpersoon aanwijzen | C33: Iemand die post, Belastingdienst en evt. school kan afhandelen. | D33: x
A34: 46143 | B34: Overzicht vaste lasten maken | C34: Lijst van abonnementen, verzekeringen en vaste lasten voor thuis; beslissen wat pauzeerbaar is. | D34: x
A36: 46174 | B36: Woningregeling uitwerken | C36: Huisoppas/onderverhuur regelen; afspraken vastleggen (sleutels, planten, onderhoud). | D36: x
A37: 46174 | B37: Abonnementen & energie optimaliseren | C37: Bepalen welke abonnementen tijdelijk stop of omlaag kunnen (sport, kranten, tv, etc.). | D37: x
A38: 46174 | B38: Auto | C38: Auto stallen of door iemand laten gebruiken; verzekering checken | D38: x
A39: 46174 | B39: Noodplan thuisfront | C39: Maken van eenvoudig draaiboek: bij schade, lekkage, storingen, belangrijke post.
A41: 46204 | B41: Onderwijs praktisch maken | C41: Lesmateriaal kopen/printen; apps installeren; basis-weekrooster maken. | D41: x
A42: 46204 | B42: Portfolio-structuur opzetten | C42: Folder/Drive/OneDrive map met submappen per maand/land; manier van verslaglegging afspreken. | D42: x
A43: 46204 | B43: Telecom & data plannen | C43: Keuze voor eSIM/roaming; per regio beste opties; automatische foto-back-up instellen.
A44: 46204 | B44: Reis-EHBO samenstellen | C44: Basis EHBO + specifieke medicatie voor kinderen; doseringen uitprinten en meenemen.
A46: 46235 | B46: Eerste en belangrijke overnachtingen controleren | C46: Checken of alle kritieke nachten (eerste nachten per continent, safari, eilanden) geboekt en bevestigd zijn.
A47: 46235 | B47: Autohuur/camperhuur dubbelchecken | C47: Alle boekingen, verzekeringen en kinderzitjes controleren; vouchercodes en voorwaarden printen.
A48: 46235 | B48: Noodcontacten & documenten in orde maken | C48: Overzicht verzekeringsnummers, alarmcentrale, ambassade, ICE-contacten; opslaan in telefoon en printen.
...

Sheet Noodnummers
A1: NOODNUMMERS WERELDREIS 2026–2027
A2: Bij direct levensgevaar: bel eerst het lokale alarmnummer. Bel daarna zo snel mogelijk Special ISIS; voor consulaire nood is Nederland Wereldwijd 24/7 bereikbaar.
A3: Land | B3: Algemeen alarm | C3: Politie | D3: Ambulance | E3: Brandweer | F3: Ambassade / consulaat | G3: Nederland Wereldwijd | H3: Ziekenhuis / medische hulp | I3: Special ISIS | J3: CZ Helpline | K3: Belangrijk
A4: Verenigde Staten | B4: 911 | C4: 911 | D4: 911 | E4: 911 | F4: Consulaat-generaal San Francisco +1 415 291 2033 | G4: +31 247 247 247 (24 uur per dag) | H4: Bij spoed: dichtstbijzijnde ER via 911. San Francisco: Zuckerberg SF General, 1001 Potrero Ave +1 628 206 8000 | I4: +1 800 694 9832 (gratis vanuit VS) Global: +31 182 544 555 | J4: +31 13 468 04 02 (24 uur per dag) | K4: Zorgkosten kunnen zeer hoog zijn. Bel Special ISIS bij opname, ongeval of repatriëring zo snel mogelijk.
A5: Fiji | B5: 911 | C5: 917 | D5: 911 | E5: 910 | F5: Geen Nederlandse ambassade in Fiji. Ambassade Wellington: +64 4 471 6390 | G5: +31 247 247 247 (24 uur per dag) | H5: Nadi Hospital: +679 670 1128 Lautoka Hospital: +679 666 0399 Op een eiland: waarschuw resort/bootoperator direct. | I5: +31 182 544 555 Goudse Alarmcentrale | J5: +31 13 468 04 02 (24 uur per dag) | K5: Ambulance- en evacuatiemogelijkheden zijn buiten de grote plaatsen en op eilanden beperkt. Geef eiland, resort en aanlegsteiger door.
A6: Australië | B6: 000 112 vanaf mobiel is alternatief | C6: 000 Niet-spoed: 131 444 | D6: 000 (spoed) | E6: 000 (spoed) | F6: Ambassade Canberra: +61 2 6220 9400 Consulaat Sydney: +61 2 8305 6800 | G6: +31 247 247 247 (24 uur per dag) | H6: Bij spoed: 000. Healthdirect verpleegkundige: 1800 022 222 (24/7) | I6: +31 182 544 555 Goudse Alarmcentrale | J6: +31 13 468 04 02 (24 uur per dag) | K6: Bel 000 alleen bij levensgevaar of tijdkritische situaties. Gebruik Healthdirect voor medische twijfel zonder acute nood.
A7: Nieuw-Zeeland | B7: 111 | C7: 111 Niet-spoed: 105 | D7: 111 | E7: 111 | F7: Ambassade Wellington +64 4 471 6390 | G7: +31 247 247 247 (24 uur per dag) | H7: Bij spoed: 111. Healthline: 0800 611 116 (24/7) | I7: +31 182 544 555 Goudse Alarmcentrale | J7: +31 13 468 04 02 (24 uur per dag) | K7: 111 is voor politie, brandweer en ambulance. Gebruik 105 alleen voor niet-dringende politiezaken.
A8: Singapore | B8: 999 politie 995 brandweer/ambulance | C8: 999 | D8: 995 | E8: 995 | F8: Ambassade Singapore +65 6737 1155 | G8: +31 247 247 247 (24 uur per dag) | H8: Kinderen: KKH Children's Emergency, 100 Bukit Timah Rd +65 6225 5554 Volwassenen: SGH Emergency, 1 Hospital Boulevard Niet-spoed: NurseFirst 6262 6262 | I8: +31 182 544 555 Goudse Alarmcentrale | J8: +31 13 468 04 02 (24 uur per dag) | K8: Gebruik tijdens jullie reis NurseFirst voor niet-levensbedreigende medische vragen.
A9: Thailand | B9: 191 algemeen/politie 1669 medisch | C9: 191 Toeristenpolitie: 1155 | D9: 1669 | E9: 199 | F9: Ambassade Bangkok +66 2 309 5200 | G9: +31 247 247 247 (24 uur per dag) | H9: Bangkok Hospital Phuket, Emergency & Trauma Center (24/7) +66 76 254 425 Elders: bel 1669 en waarschuw hotel/resort. | I9: +31 182 544 555 Goudse Alarmcentrale | J9: +31 13 468 04 02 (24 uur per dag) | K9: Toeristenpolitie 1155 biedt 24/7 hulp in meerdere talen. Bewaar de naam en het adres van de accommodatie ook in het Thais.
A10: Qatar | B10: 999 | C10: 999 | D10: 999 | E10: 999 | F10: Ambassade Doha +974 4495 4700 | G10: +31 247 247 247 (24 uur per dag) | H10: Hamad General Hospital, Adult Emergency (24/7) +974 4434 2421 / 2422 Kinderen t/m 14 jaar: Pediatric Emergency Center via 999. | I10: +31 182 544 555 Goudse Alarmcentrale | J10: +31 13 468 04 02 (24 uur per dag) | K10: 999 verbindt met politie, Civil Defence en ambulance. Kinderen t/m 14 jaar gaan naar een Pediatric Emergency Center.
A11: Tanzania | B11: 112 politie 115 ambulance | C11: 112 | D11: 115 | E11: 114 | F11: Ambassade Dar es Salaam +255 22 219 4000 | G11: +31 247 247 247 (24 uur per dag) | H11: Arusha Lutheran Medical Centre (24/7) Spoed: +255 766 909 113 Tijdens safari: informeer gids/lodge direct voor vervoer of evacuatie. | I11: +31 182 544 555 Goudse Alarmcentrale | J11: +31 13 468 04 02 (24 uur per dag) | K11: De bereikbaarheid en responstijd kunnen buiten steden beperkt zijn. Laat gids/lodge coördineren en bel de verzekeraar direct bij mogelijke evacuatie.
A23: Gecontroleerd op 12 augustus 2026 • Nummers kunnen wijzigen: controleer kort voor vertrek en bewaar dit bestand ook offline.

Sheet Paklijst
A2: DOCUMENTEN & ADMINISTRATIE
A3: Per persoon
A4: Paspoort
A5: Kopie paspoort (papier)
A6: Digitale kopie paspoort
A7: Reisverzekering
A8: Vliegtickets/e-tickets
A9: Zorgpas
A10: Bankpas
A11: Creditcard
A12: Gezamenlijk
A13: Rijbewijs
... A228: Reservekleding kinderen

Sheet Dagplanning - USA
A1: Datum | B1: Dag | C1: Route | D1: Beschrijving | E1: Afstand | F1: Reistijd | G1: informatie | H1: Google maps | I1: Kolom 1
A2: Datum | B2: Dag | C2: Route | D2: Beschrijving | E2: Afstand | F2: Reistijd | G2: informatie | H2: Google maps | I2: Komoot wandeling
A3: 46284 | B3: 1 | C3: ✈️ Aankomst San Francisco | D3: Aankomst, rustig bijkomen. Aankomst tijd 13:50 uur - Avondwandeling langs de baai. | H3: https://www.google.com/maps/dir/?api=1&origin=San%20Francisco%20International%20Airport%2C%20San%20Francisco%2C%20CA&destination=Holiday%20Inn%20San%20Francisco-Golden%20Gateway%2C%201500%20Van%20Ness%20Avenue%2C%20San%20Francisco%2C%20CA%2094109&waypoints=Holiday%20Inn%20San%20Francisco-Golden%20Gateway%2C%201500%20Van%20Ness%20Avenue%2C%20San%20Francisco%2C%20CA%2094109%7CFort%20Mason%20Great%20Meadow%2C%20Bay%20Street%2C%20San%20Francisco%2C%20CA%7CAquatic%20Park%20Cove%2C%20San%20Francisco%2C%20CA
A4: 46285 | B4: 2 | C4: San Francisco | D4: - 09:00 Cable car rit (Powell–Hyde) Powell Street → Fisherman's Wharf - 10:00 Pier 39 – zeeleeuwen Pier 39 Korte stop + wandelen - 11:30 Lunch Fisherman's Wharf Fisherman's Wharf Eerder lunchen voorkomt drukte - 13:00 Museum keuze (Exploratorium of California Academy of Sciences) - 15:30 Chinatown verkennen Chinatown (Grant Avenue) Kort + gericht - 17:30 Diner North Beach North Beach (Little Italy) Rustige afsluiter dag - 19:00 Einde dag / terug naar hotel Geen late avond i.v.m. jetlag | H4: https://www.google.com/maps/dir/?api=1&origin=Holiday%20Inn%20San%20Francisco-Golden%20Gateway%2C%201500%20Van%20Ness%20Avenue%2C%20San%20Francisco%2C%20CA%2094109&destination=Holiday%20Inn%20San%20Francisco-Golden%20Gateway%2C%201500%20Van%20Ness%20Avenue%2C%20San%20Francisco%2C%20CA%2094109&waypoints=Powell%20Street%20Cable%20Car%20Turnaround%2C%20Powell%20Street%20and%20Market%20Street%2C%20San%20Francisco%2C%20CA%7CHyde%20Street%20and%20Beach%20Street%2C%20San%20Francisco%2C%20CA%7CSea%20Lion%20Viewing%20Area%2C%20Pier%2039%2C%20San%20Francisco%2C%20CA%7CFisherman's%20Wharf%2C%20San%20Francisco%2C%20CA%7CExploratorium%2C%20Pier%2015%2C%20San%20Francisco%2C%20CA%2094111%7CDragon's%20Gate%2C%20Bush%20Street%20and%20Grant%20Avenue%2C%20San%20Francisco%2C%20CA%7CNorth%20Beach%2C%20San%20Francisco%2C%20CA&travelmode=transit
A5: 46286 | B5: 3 | C5: San Francisco | D5: - 09:00 Start fietstocht Golden Gate vanaf Fisherman's Wharf - 10:30 Golden Gate Bridge viewpoint Foto + korte pauze - 11:30 Aankomst Sausalito Sausalito wandelen + ijsje - 12:00 Lunch Sausalito Sausalito waterkant - 14:00 Ferry terug naar San Francisco Sausalito → Pier 41/39 niet te laat i.v.m. drukte - 15:30 Lombard Street Lombard Street 20–30 min stop - 16:30 Mission District of Golden Gate Par - 18:00 Twin Peaks (optioneel sunset) Uitsluitend bij helder weer - 19:30 Einde dag Avond vrij | G5: https://www.blazingsaddles.com/ https://bikeandview.com/bike-rental | H5: https://www.google.com/maps/dir/?api=1&origin=Holiday%20Inn%20San%20Francisco-Golden%20Gateway%2C%201500%20Van%20Ness%20Avenue%2C%20San%20Francisco%2C%20CA%2094109&destination=Holiday%20Inn%20San%20Francisco-Golden%20Gateway%2C%201500%20Van%20Ness%20Avenue%2C%20San%20Francisco%2C%20CA%2094109&waypoints=Fisherman's%20Wharf%2C%20San%20Francisco%2C%20CA%7CGolden%20Gate%20Bridge%20Welcome%20Center%2C%20San%20Francisco%2C%20CA%7CGolden%20Gate%20Bridge%20Vista%20Point%2C%20US-101%2C%20Sausalito%2C%20CA%2094965%7CSausalito%20Ferry%20Landing%2C%20Sausalito%2C%20CA%7CSan%20Francisco%20Ferry%20Building%2C%201%20Ferry%20Building%2C%20San%20Francisco%2C%20CA%7CFisherman's%20Wharf%2C%20San%20Francisco%2C%20CA%7CLombard%20Street%2C%20San%20Francisco%2C%20CA%7CGolden%20Gate%20Park%2C%20San%20Francisco%2C%20CA%7CTwin%20Peaks%2C%20San%20Francisco%2C%20CA&travelmode=bicycling
A6: 46287 | B6: 4 | C6: San Francisco → Monterey / Carmel | D6: - 09:00 Vertrek richting Monterey via Highway 1. - Optioneel stop: Santa Cruz Boardwalk of pier met zeeleeuwen. - 12:00 Aankomst Monterey – lunch. - 13:00 17-Mile Drive bij Carmel-by-the-Sea (tol ~$12). - 14:30 Point Lobos State Reserve – max 1,5 uur. Zeeotters bij Cypress Grove & China Cove. - 16:30 Carmel-by-the-Sea dorpje verkennen. | E6: 200 | F6: 2.3 | H6: https://www.google.com/maps/dir/?api=1&origin=433%20Powell%20Street%2C%20San%20Francisco%2C%20CA%2094102&destination=707%20Pacific%20Street%2C%20Monterey%2C%20CA%2093940&travelmode=driving&waypoints=Santa%20Cruz%20Wharf%2C%20Santa%20Cruz%2C%20CA%7COld%20Fisherman's%20Wharf%2C%20Monterey%2C%20CA%7CPacific%20Grove%20Gate%2C%2017%20Mile%20Drive%2C%20CA%7CSpanish%20Bay%2C%20Pebble%20Beach%2C%20CA%7CLone%20Cypress%2C%20Pebble%20Beach%2C%20CA%7CPoint%20Lobos%20State%20Natural%20Reserve%2C%20CA%7CCarmel-by-the-Sea%2C%20CA | I6: https://www.komoot.com/nl-nl/tour/2614904856 https://www.komoot.com/nl-nl/tour/2614897863
A7: 46288 | B7: 5 | C7: Monterey / Carmel → San Simeon (Big Sur route) | D7: - 10:00–13:00 Whale watch tour vanuit Monterey (boek vooraf!). - 14:00 Vertrek richting San Simeon via Highway 1. - Bixby Creek Bridge & Hurricane Point – fotostop. - Julia Pfeiffer Burns SP – McWay Falls viewpoint (iconische waterval, 15 min). - Pfeiffer Big Sur SP óf Andrew Molera – één korte wandeling (kies vooraf). - Elephant Seals bij Piedras Blancas – gratis, indrukwekkend! | E7: 240 | F7: 2.3 | H7: https://www.google.com/maps/dir/?api=1&origin=707%20Pacific%20Street%2C%20Monterey%2C%20CA%2093940&destination=9260%20Castillo%20Drive%2C%20San%20Simeon%2C%20CA%2093452&travelmode=driving&waypoints=Monterey%20Bay%20Whale%20Watch%2C%20Monterey%2C%20CA%7CBixby%20Creek%20Bridge%2C%20CA%7CHurricane%20Point%20View%2C%20CA%7CPfeiffer%20Big%20Sur%20State%20Park%2C%20CA%7CMcWay%20Falls%2C%20CA%7CPiedras%20Blancas%20Elephant%20Seal%20Rookery%2C%20CA | I7: https://www.komoot.com/nl-nl/tour/2702548958 https://www.komoot.com/nl-nl/tour/2614928316 https://www.komoot.com/nl-nl/tour/2614923839
A8: 46289 | B8: 6 | C8: San Simeon → Santa Barbara | D8: - 09:00 Vertrek richting Morro Bay. - Morro Bay & Morro Rock – korte stop, strandwandeling. - 11:30 Lunch aan zee in Morro Bay. - 13:00 Verder naar Santa Barbara. - Santa Barbara verkennen: State Street, pier en strandpromenade. - Optioneel: kijk of er een raketlancering is bij Vandenberg (check 24u van tevoren). | E8: 220 | F8: 2.15 | H8: https://www.google.com/maps/dir/?api=1&origin=9260%20Castillo%20Drive%2C%20San%20Simeon%2C%20CA%2093452&destination=180%20Avenue%20of%20Flags%2C%20Buellton%2C%20CA%2093427&travelmode=driving&waypoints=Morro%20Rock%2C%20Morro%20Bay%2C%20CA%7CState%20Street%2C%20Santa%20Barbara%2C%20CA%7CStearns%20Wharf%2C%20Santa%20Barbara%2C%20CA
A9: 46290 | B9: 7 | C9: Santa Barbara → Los Angeles | D9: - 09:30 Vertrek via Malibu – meerdere strandstops mogelijk. - El Matador Beach – wilde rotsachtige stranden, mooie foto's. - Zuma Beach – brede zandsstranden, goed voor kinderen. - 13:00 Lunch in Malibu. - 14:30 Aankomst Venice Beach. | E9: 165 | F9: 3 | H9: https://www.google.com/maps/dir/?api=1&origin=180%20Avenue%20of%20Flags%2C%20Buellton%2C%20CA%2093427&destination=14000%20Palawan%20Way%2C%20Marina%20del%20Rey%2C%20CA%2090292&travelmode=driving&waypoints=Zuma%20Beach%2C%20Malibu%2C%20CA%7CEl%20Matador%20State%20Beach%2C%20Malibu%2C%20CA%7CMalibu%20Pier%2C%20Malibu%2C%20CA%7CVenice%20Beach%2C%20Los%20Angeles%2C%20CA
A10: 46291 | B10: 8 | C10: Los Angeles | D10: Dag 1 – Hollywood & Griffith Park - 09:00 Hollywood Walk of Fame & TCL Chinese Theatre. - 10:30 Dolby Theatre (bekend van de Oscars). - 12:00 Lunch in Hollywood. - 13:30 Griffith Park – DASH bus of Uber (parkeren is drama). - 14:00 Griffith Observatory – uitzicht over de stad én Hollywood Sign. - 17:30 Zonsondergang bij het observatorium. - Optioneel: kleine hike richting Hollywood Sign | E10: 30 | F10: 0.3 | H10: https://www.google.com/maps/dir/?api=1&origin=14000%20Palawan%20Way%2C%20Marina%20del%20Rey%2C%20CA%2090292&destination=14000%20Palawan%20Way%2C%20Marina%20del%20Rey%2C%20CA%2090292&travelmode=driving&waypoints=Hollywood%20Walk%20of%20Fame%2C%20Los%20Angeles%2C%20CA%7CTCL%20Chinese%20Theatre%2C%20Los%20Angeles%2C%20CA%7CDolby%20Theatre%2C%20Los%20Angeles%2C%20CA%7CGriffith%20Observatory%2C%20Los%20Angeles%2C%20CA
A11: 46292 | B11: 9 | C11: Los Angeles | D11: Dag 2 – Stranden & relaxen - 09:00 Santa Monica Pier & Beach – iconisch, leuk met kinderen. - 10:30 Fietstocht Venice Beach → Santa Monica (huur e-bikes of fietsen). - 12:30 Lunch op de boulevard. - 14:00 Venice Canals – charmante wandeling langs bruggetjes en kanalen. - 16:00 Vrije tijd / zwemmen. - 18:30 Diner bij Third Street Promenade, Santa Monica. | H11: https://www.google.com/maps/dir/?api=1&origin=14000%20Palawan%20Way%2C%20Marina%20del%20Rey%2C%20CA%2090292&destination=14000%20Palawan%20Way%2C%20Marina%20del%20Rey%2C%20CA%2090292&travelmode=bicycling&waypoints=Santa%20Monica%20Pier%2C%20Santa%20Monica%2C%20CA%7CVenice%20Beach%20Skatepark%2C%20Los%20Angeles%2C%20CA%7CVenice%20Canals%2C%20Los%20Angeles%2C%20CA%7CThird%20Street%20Promenade%2C%20Santa%20Monica%2C%20CA
A12: 46293 | B12: 10 | C12: Los Angeles → Anaheim | D12: Dag 3 – Cultuur & Downtown LA - 09:30 The Broad Museum (gratis, reserveren!) of LACMA – kies één. - Walt Disney Concert Hall – architectonisch hoogtepunt, buiten bekijken. - El Pueblo de Los Angeles – historische wijk met Mexicaanse invloeden. - Lunch in Little Tokyo of Chinatown. - 14:30 Rijden naar Anaheim. | E12: 30 | F12: 1 | H12: https://www.google.com/maps/dir/?api=1&origin=14000%20Palawan%20Way%2C%20Marina%20del%20Rey%2C%20CA%2090292&destination=11767%20Harbor%20Boulevard%2C%20Garden%20Grove%2C%20CA%2092840&travelmode=driving&waypoints=The%20Broad%2C%20Los%20Angeles%2C%20CA%7CWalt%20Disney%20Concert%20Hall%2C%20Los%20Angeles%2C%20CA%7CEl%20Pueblo%20de%20Los%20Angeles%20Historical%20Monument%2C%20Los%20Angeles%2C%20CA%7CLittle%20Tokyo%2C%20Los%20Angeles%2C%20CA
A13: 46294 | B13: 11 | C13: Anaheim | D13: DISNEY | E13: - | F13: - | H13: https://www.google.com/maps/dir/?api=1&origin=11767%20Harbor%20Boulevard%2C%20Garden%20Grove%2C%20CA%2092840&destination=11767%20Harbor%20Boulevard%2C%20Garden%20Grove%2C%20CA%2092840&travelmode=driving&waypoints=Mickey%20and%20Friends%20Parking%20Structure%2C%20Anaheim%2C%20CA
A14: 46295 | B14: 12 | C14: Anaheim → Joshua Tree → Kingman | D14: - 07:30 Vroeg vertrek – lange dag! - 10:00 Joshua Tree National Park – Keys View (panoramisch uitzicht). - Korte hike: Skull Rock Nature Trail (2,7 km, kindvriendelijk). - 12:30 Picknick of lunch in/bij de park. | E14: 450 | F14: 5.3 | H14: https://www.google.com/maps/dir/?api=1&origin=11767%20Harbor%20Boulevard%2C%20Garden%20Grove%2C%20CA%2092840&destination=2815%20East%20Andy%20Devine%20Avenue%2C%20Kingman%2C%20AZ%2086401&travelmode=driving&waypoints=Joshua%20Tree%20National%20Park%20West%20Entrance%2C%20CA%7CKeys%20View%2C%20Joshua%20Tree%20National%20Park%2C%20CA%7CSkull%20Rock%2C%20Joshua%20Tree%20National%20Park%2C%20CA%7CJoshua%20Tree%20National%20Park%20North%20Entrance%2C%20CA | I14: https://www.komoot.com/nl-nl/tour/2614761117 https://www.komoot.com/nl-nl/tour/2702560442 https://www.komoot.com/nl-nl/tour/2614752433 https://www.komoot.com/nl-nl/tour/2687144756 https://www.komoot.com/nl-nl/tour/2687144846
A15: 46296 | B15: 13 | C15: Kingman → Grand Canyon | D15: - 09:00 Vertrek via Route 66. - Stop bij Seligman – historisch Route 66 stadje, Westside Lilo's Café. - 14:00 Aankomst Tusayan - 14:45 IMAX Grand Canyon Movie in Tusayan (goede introductie voor kinderen). - 16:00 Grand Canyon South Rim – Visitor Center & Mather Point. - 17:30 Hopi Point voor zonsondergang (shuttle Hermit Road) óf Yaki Point (eigen auto). - 18:13 Zonsondergang South Rim. - 19:00 Terug naar Tusayan voor diner. | E15: 230 | F15: 3.3 | H15: https://www.google.com/maps/dir/?api=1&origin=2815%20East%20Andy%20Devine%20Avenue%2C%20Kingman%2C%20AZ%2086401&destination=226%20Highway%2064%2C%20Tusayan%2C%20AZ%2086023&travelmode=driving&waypoints=Seligman%2C%20AZ%7CGrand%20Canyon%20IMAX%20Theater%2C%20Tusayan%2C%20AZ%7CGrand%20Canyon%20Visitor%20Center%2C%20AZ%7CMather%20Point%2C%20Grand%20Canyon%2C%20AZ%7CGrand%20Canyon%20Village%2C%20AZ
A16: 46297 | B16: 14 | C16: Grand Canyon → Kayenta | D16: - 09:00 Terug naar South Rim. - 09:30 Rim Trail – 5 km heen (evt bus terug), prachtige rand-wandeling. - 11:00 Scenic Drive richting Desert View: Grandview, Moran & Lipan Point. - 12:30 Navajo Point – picknick (neem eigen eten mee). - 14:30 Vertrek richting Kayenta. | E16: 200 | F16: 2.3 | H16: https://www.google.com/maps/dir/?api=1&origin=226%20Highway%2064%2C%20Tusayan%2C%20AZ%2086023&destination=Hampton%20Inn%20Kayenta%2C%20US%20Highway%20160%2C%20Kayenta%2C%20AZ%2086033&travelmode=driving&waypoints=Mather%20Point%2C%20Grand%20Canyon%2C%20AZ%7CBright%20Angel%20Trailhead%2C%20Grand%20Canyon%2C%20AZ%7CGrandview%20Point%2C%20Grand%20Canyon%2C%20AZ%7CMoran%20Point%2C%20Grand%20Canyon%2C%20AZ%7CLipan%20Point%2C%20Grand%20Canyon%2C%20AZ%7CNavajo%20Point%2C%20Grand%20Canyon%2C%20AZ%7CDesert%20View%20Watchtower%2C%20Grand%20Canyon%2C%20AZ | I16: https://www.komoot.com/nl-nl/tour/2614048812 https://www.komoot.com/nl-nl/tour/2614052612
A17: 46298 | B17: 15 | C17: Bluff (Monument Valley) | D17: - 08:00 vertrek naar Monument valley - 09:00 Wildcat Trail (6,4 km) – vroeg vanwege warmte, ook voor kinderen. - Navajo Tribal Park – uitzichtpunten langs de Valley Drive (eigen auto, ~30 km lus). - Lunch bij foodtruck of The View Restaurant. - Middag: richting Mexican Hat → Forest Gump Point (Highway 163, iconische foto!). - Goosenecks State Park – spectaculaire meanders van de San Juan River. | E17: 100 | F17: 1.3 | H17: https://www.google.com/maps/dir/?api=1&origin=Hampton%20Inn%20Kayenta%2C%20US%20Highway%20160%2C%20Kayenta%2C%20AZ%2086033&destination=The%20View%20Hotel%2C%20Monument%20Valley%20Tribal%20Park%2C%20AZ%2084536&travelmode=driving&waypoints=Wildcat%20Trailhead%2C%20Monument%20Valley%2C%20AZ%7CJohn%20Ford's%20Point%2C%20Monument%20Valley%2C%20AZ%7CForrest%20Gump%20Point%2C%20Mexican%20Hat%2C%20UT%7CMexican%20Hat%2C%20UT%7CGoosenecks%20State%20Park%2C%20UT | I17: https://www.komoot.com/nl-nl/tour/2614787726 https://www.komoot.com/nl-nl/tour/3015176711 https://www.komoot.com/nl-nl/tour/2614807185 https://www.komoot.com/nl-nl/tour/2614793120 https://www.komoot.com/nl-nl/tour/2614804991
A18: 46299 | B18: 16 | C18: Bluff (Monument Valley) → Page → Kanab | D18: - 09:10 Vertrek uiterlijk – Canyon-X tour (2u 20 rijden. - Canyon-X bezoek om 11:40. - Horseshoe Bend – 1,5 uur retour wandeling (let op: geen hekken, pas op met kinderen). - Lunch in Page. - 15:00 Rijden naar Kanab (~1-1,5 uur). | E18: 330 | F18: 3.5 | H18: https://www.google.com/maps/dir/?api=1&origin=The%20View%20Hotel%2C%20Monument%20Valley%20Tribal%20Park%2C%20AZ%2084536&destination=217%20South%20100%20East%2C%20Kanab%2C%20UT%2084741&travelmode=driving&waypoints=Antelope%20Canyon%20X%20by%20Taadidiin%20Tours%2C%20AZ%7CHorseshoe%20Bend%2C%20Page%2C%20AZ%7CPage%2C%20AZ
A19: 46300 | B19: 17 | C19: Kanab → Bryce Canyon NP | D19: - 09:00 Vertrek richting Bryce Canyon. - Navajo Loop Trail (2,4 km) – door hoodoos, kindvriendelijk maar steil omhoog. Combineer met Peek-a-Boo Loop = totaal ~8 km (voor fitte kinderen). - Lunch bij het park of Bryce Canyon City. - Bristlecone Loop Trail (2 km, mooie oude pijnbomen). - Bryce point naar Inspiration 2,7km of sunset point 3,7 km (rim trail shuttle bus nemen) - Zonsondergang bij Bryce Point. https://www.nps.gov/brca/planyourvisit/shuttle.htm | E19: 140 | F19: 2 | H19: https://www.google.com/maps/dir/?api=1&origin=217%20South%20100%20East%2C%20Kanab%2C%20UT%2084741&destination=Bryce%20Vistas%2C%20270%20East%201250%20North%2C%20Tropic%2C%20UT%2084776&travelmode=driving&waypoints=Sunset%20Point%2C%20Bryce%20Canyon%20National%20Park%2C%20UT%7CRainbow%20Point%2C%20Bryce%20Canyon%20National%20Park%2C%20UT%7CInspiration%20Point%2C%20Bryce%20Canyon%20National%20Park%2C%20UT%7CBryce%20Point%2C%20Bryce%20Canyon%20National%20Park%2C%20UT | I19: https://www.komoot.com/nl-nl/tour/2688381072 https://www.komoot.com/nl-nl/tour/2688359078 https://www.komoot.com/nl-nl/tour/2688333419 https://www.komoot.com/nl-nl/tour/2688333470 https://www.komoot.com/nl-nl/tour/2688334893 https://www.komoot.com/nl-nl/tour/2688356249 https://www.komoot.com/nl-nl/tour/3018387564 https://www.komoot.com/nl-nl/tour/2688338966 https://www.komoot.com/nl-nl/tour/2688394606
A20: 46301 | B20: 18 | C20: Bryce Canyon → Zion NP | D20: - 08:00 Ochtendwandeling nog in Bryce (golden hour 07:00 -08:30). - 10:00 Vertrek via Red Canyon richting Zion. - Evt. lunch bij Archie's Food to Die For (GF-opties) onderweg. - Aankomst Zion – Canyon Overlook Trail (parkeer eerste vrije plek DRUK!!). - Watchman Trail als Canyon Overlook te druk is (3,3 km, mooi uitzicht). - Inchecken The Riv at Zion, Virgin (239 UT-9). - Zwemmen bij accommodatie. | E20: 140 | F20: 2 | H20: https://www.google.com/maps/dir/?api=1&origin=Bryce%20Vistas%2C%20270%20East%201250%20North%2C%20Tropic%2C%20UT%2084776&destination=865%20Zion%20Park%20Boulevard%2C%20Springdale%2C%20UT%2084767&travelmode=driving&waypoints=Sunrise%20Point%2C%20Bryce%20Canyon%20National%20Park%2C%20UT%7CRed%20Canyon%20Visitor%20Center%2C%20UT%7CArchie's%20Food%20to%20Die%20For%2C%20Orderville%2C%20UT%7CCanyon%20Overlook%20Trailhead%2C%20Zion%20National%20Park%2C%20UT | I20: https://www.komoot.com/nl-nl/tour/2614846720 https://www.komoot.com/nl-nl/tour/3018369235
